2017-03-18 01:25:06,779 - clonegod.person - ERROR - Failed to open file
Traceback (most recent call last):
  File "clonegod\person.py", line 19, in tryError
    open('/path/to/does/not/exist', 'rb')
IOError: [Errno 2] No such file or directory: '/path/to/does/not/exist'
2017-03-18 02:02:07,598 - clonegod.person - ERROR - Failed to open file
Traceback (most recent call last):
  File "clonegod\person.py", line 19, in tryError
    open('/path/to/does/not/exist', 'rb')
IOError: [Errno 2] No such file or directory: '/path/to/does/not/exist'
2017-03-18 02:09:22,571 - clonegod.person - ERROR - Failed to open file
Traceback (most recent call last):
  File "clonegod\person.py", line 19, in tryError
    open('/path/to/does/not/exist', 'rb')
IOError: [Errno 2] No such file or directory: '/path/to/does/not/exist'
2017-03-18 02:28:17,448 - clonegod.person - ERROR - Failed to open file
Traceback (most recent call last):
  File "clonegod\person.py", line 19, in tryError
    open('/path/to/does/not/exist', 'rb')
IOError: [Errno 2] No such file or directory: '/path/to/does/not/exist'
